2020-04-21 00:02:16 Main         INFO     Starting
2020-04-21 16:30:52 Main         INFO     Starting
2020-04-21 16:31:36 Main         DEBUG    Starting
2020-04-21 16:33:12 Main         INFO     Starting
2020-04-21 23:09:47 Main         INFO     Starting
2020-04-21 23:09:47 root         ERROR    'Namespace' object has no attribute 'config'
Traceback (most recent call last):
  File "/home/drkostas/Insync/OneDrive/Projects/template_python_project/main.py", line 74, in <module>
    main()
  File "/home/drkostas/Insync/OneDrive/Projects/template_python_project/main.py", line 19, in main
    configuration = Configuration(args.config)
AttributeError: 'Namespace' object has no attribute 'config'

2020-04-21 23:10:16 Main         INFO     Starting
2020-04-21 23:10:16 root         ERROR    [Errno 2] No such file or directory: '/home/drkostas/Insync/OneDrive/Projects/template_python_project/configuration/yml_config.json'
Traceback (most recent call last):
  File "/home/drkostas/Insync/OneDrive/Projects/template_python_project/main.py", line 74, in <module>
    main()
  File "/home/drkostas/Insync/OneDrive/Projects/template_python_project/main.py", line 19, in main
    configuration = Configuration(config_src=args.config_file)
  File "/home/drkostas/Insync/OneDrive/Projects/template_python_project/configuration/configuration.py", line 28, in __init__
    CONFIGURATION_SCHEMA = cls.load_configuration_schema(config_schema_path=cls.CONFIG_SCHEMA_PATH)
  File "/home/drkostas/Insync/OneDrive/Projects/template_python_project/configuration/configuration.py", line 40, in load_configuration_schema
    with open('/'.join([os.path.dirname(os.path.realpath(__file__)), config_schema_path])) as f:
FileNotFoundError: [Errno 2] No such file or directory: '/home/drkostas/Insync/OneDrive/Projects/template_python_project/configuration/yml_config.json'

2020-04-21 23:10:42 Main         INFO     Starting
2020-04-21 23:10:42 root         ERROR    could not determine a constructor for the tag '!ENV'
  in "confs/template_conf.yml", line 4, column 14
Traceback (most recent call last):
  File "/home/drkostas/Insync/OneDrive/Projects/template_python_project/main.py", line 74, in <module>
    main()
  File "/home/drkostas/Insync/OneDrive/Projects/template_python_project/main.py", line 19, in main
    configuration = Configuration(config_src=args.config_file)
  File "/home/drkostas/Insync/OneDrive/Projects/template_python_project/configuration/configuration.py", line 30, in __init__
    cls.config, cls.config_path = cls.load_yml(config_src=config_src)
  File "/home/drkostas/Insync/OneDrive/Projects/template_python_project/configuration/configuration.py", line 47, in load_yml
    config = yaml.load(config_src)
  File "/home/drkostas/Insync/OneDrive/Projects/template_python_project/venv/lib/python3.6/site-packages/yaml/__init__.py", line 114, in load
    return loader.get_single_data()
  File "/home/drkostas/Insync/OneDrive/Projects/template_python_project/venv/lib/python3.6/site-packages/yaml/constructor.py", line 51, in get_single_data
    return cls.construct_document(node)
  File "/home/drkostas/Insync/OneDrive/Projects/template_python_project/venv/lib/python3.6/site-packages/yaml/constructor.py", line 60, in construct_document
    for dummy in generator:
  File "/home/drkostas/Insync/OneDrive/Projects/template_python_project/venv/lib/python3.6/site-packages/yaml/constructor.py", line 413, in construct_yaml_map
    value = cls.construct_mapping(node)
  File "/home/drkostas/Insync/OneDrive/Projects/template_python_project/venv/lib/python3.6/site-packages/yaml/constructor.py", line 218, in construct_mapping
    return super().construct_mapping(node, deep=deep)
  File "/home/drkostas/Insync/OneDrive/Projects/template_python_project/venv/lib/python3.6/site-packages/yaml/constructor.py", line 143, in construct_mapping
    value = cls.construct_object(value_node, deep=deep)
  File "/home/drkostas/Insync/OneDrive/Projects/template_python_project/venv/lib/python3.6/site-packages/yaml/constructor.py", line 100, in construct_object
    data = constructor(cls, node)
  File "/home/drkostas/Insync/OneDrive/Projects/template_python_project/venv/lib/python3.6/site-packages/yaml/constructor.py", line 429, in construct_undefined
    node.start_mark)
yaml.constructor.ConstructorError: could not determine a constructor for the tag '!ENV'
  in "confs/template_conf.yml", line 4, column 14

2020-04-21 23:11:14 Main         INFO     Starting
2020-04-21 23:11:14 root         ERROR    could not determine a constructor for the tag '!ENV'
  in "confs/template_conf.yml", line 4, column 14
Traceback (most recent call last):
  File "/home/drkostas/Insync/OneDrive/Projects/template_python_project/main.py", line 74, in <module>
    main()
  File "/home/drkostas/Insync/OneDrive/Projects/template_python_project/main.py", line 19, in main
    configuration = Configuration(config_src=args.config_file)
  File "/home/drkostas/Insync/OneDrive/Projects/template_python_project/configuration/configuration.py", line 30, in __init__
    cls.config, cls.config_path = cls.load_yml(config_src=config_src)
  File "/home/drkostas/Insync/OneDrive/Projects/template_python_project/configuration/configuration.py", line 47, in load_yml
    config = yaml.load(config_src)
  File "/home/drkostas/Insync/OneDrive/Projects/template_python_project/venv/lib/python3.6/site-packages/yaml/__init__.py", line 114, in load
    return loader.get_single_data()
  File "/home/drkostas/Insync/OneDrive/Projects/template_python_project/venv/lib/python3.6/site-packages/yaml/constructor.py", line 51, in get_single_data
    return cls.construct_document(node)
  File "/home/drkostas/Insync/OneDrive/Projects/template_python_project/venv/lib/python3.6/site-packages/yaml/constructor.py", line 60, in construct_document
    for dummy in generator:
  File "/home/drkostas/Insync/OneDrive/Projects/template_python_project/venv/lib/python3.6/site-packages/yaml/constructor.py", line 413, in construct_yaml_map
    value = cls.construct_mapping(node)
  File "/home/drkostas/Insync/OneDrive/Projects/template_python_project/venv/lib/python3.6/site-packages/yaml/constructor.py", line 218, in construct_mapping
    return super().construct_mapping(node, deep=deep)
  File "/home/drkostas/Insync/OneDrive/Projects/template_python_project/venv/lib/python3.6/site-packages/yaml/constructor.py", line 143, in construct_mapping
    value = cls.construct_object(value_node, deep=deep)
  File "/home/drkostas/Insync/OneDrive/Projects/template_python_project/venv/lib/python3.6/site-packages/yaml/constructor.py", line 100, in construct_object
    data = constructor(cls, node)
  File "/home/drkostas/Insync/OneDrive/Projects/template_python_project/venv/lib/python3.6/site-packages/yaml/constructor.py", line 429, in construct_undefined
    node.start_mark)
yaml.constructor.ConstructorError: could not determine a constructor for the tag '!ENV'
  in "confs/template_conf.yml", line 4, column 14

2020-04-21 23:31:49 Main         INFO     Starting
2020-04-21 23:32:44 Main         INFO     Starting
2020-04-21 23:32:44 Main         INFO     Dropbox Apikey: DROPBOX_API_KEY
2020-04-21 23:33:19 Main         INFO     Starting
2020-04-21 23:33:19 Main         INFO     Dropbox Apikey: tesapikey
2020-04-21 23:37:59 Main         INFO     Starting
2020-04-21 23:37:59 Main         INFO     Dropbox Apikey: tesapikey8UYshyEvE2gAAAAAAAAs1bCsnuW6mtjsAYyltJRVVum9xXlx_nSMv6oIeAzZfKEj
2020-04-21 23:40:26 Main         INFO     Starting
2020-04-21 23:40:26 dropbox      INFO     Request to files/list_folder
2020-04-21 23:40:27 root         ERROR    BadInputError('82d166660a65f869d75fd03303c82d26', 'Error in call to API function "files/list_folder": The given OAuth 2 access token is malformed.')
Traceback (most recent call last):
  File "/home/drkostas/Insync/OneDrive/Projects/template_python_project/main.py", line 76, in <module>
    main()
  File "/home/drkostas/Insync/OneDrive/Projects/template_python_project/main.py", line 22, in main
    print(cloud_store.ls(path='/'))
  File "/home/drkostas/Insync/OneDrive/Projects/template_python_project/cloudstore/dropbox_cloudstore.py", line 92, in ls
    files_list = cls.__handler__.files_list_folder(path=path)
  File "/home/drkostas/Insync/OneDrive/Projects/template_python_project/venv/lib/python3.6/site-packages/dropbox/base.py", line 2121, in files_list_folder
    None,
  File "/home/drkostas/Insync/OneDrive/Projects/template_python_project/venv/lib/python3.6/site-packages/dropbox/dropbox.py", line 316, in request
    timeout=timeout)
  File "/home/drkostas/Insync/OneDrive/Projects/template_python_project/venv/lib/python3.6/site-packages/dropbox/dropbox.py", line 463, in request_json_string_with_retry
    timeout=timeout)
  File "/home/drkostas/Insync/OneDrive/Projects/template_python_project/venv/lib/python3.6/site-packages/dropbox/dropbox.py", line 566, in request_json_string
    raise BadInputError(request_id, r.text)
dropbox.exceptions.BadInputError: BadInputError('82d166660a65f869d75fd03303c82d26', 'Error in call to API function "files/list_folder": The given OAuth 2 access token is malformed.')

2020-04-21 23:42:16 Main         INFO     Starting
2020-04-21 23:42:16 dropbox      INFO     Request to files/list_folder
2020-04-21 23:42:17 root         ERROR    BadInputError('ed64005fa471cbedbab9c2ae336f0dab', 'Error in call to API function "files/list_folder": The given OAuth 2 access token is malformed.')
Traceback (most recent call last):
  File "/home/drkostas/Insync/OneDrive/Projects/template_python_project/main.py", line 76, in <module>
    main()
  File "/home/drkostas/Insync/OneDrive/Projects/template_python_project/main.py", line 22, in main
    print(cloud_store.ls(path='/'))
  File "/home/drkostas/Insync/OneDrive/Projects/template_python_project/cloudstore/dropbox_cloudstore.py", line 94, in ls
    files_list = cls.__handler__.files_list_folder(path=path)
  File "/home/drkostas/Insync/OneDrive/Projects/template_python_project/venv/lib/python3.6/site-packages/dropbox/base.py", line 2121, in files_list_folder
    None,
  File "/home/drkostas/Insync/OneDrive/Projects/template_python_project/venv/lib/python3.6/site-packages/dropbox/dropbox.py", line 316, in request
    timeout=timeout)
  File "/home/drkostas/Insync/OneDrive/Projects/template_python_project/venv/lib/python3.6/site-packages/dropbox/dropbox.py", line 463, in request_json_string_with_retry
    timeout=timeout)
  File "/home/drkostas/Insync/OneDrive/Projects/template_python_project/venv/lib/python3.6/site-packages/dropbox/dropbox.py", line 566, in request_json_string
    raise BadInputError(request_id, r.text)
dropbox.exceptions.BadInputError: BadInputError('ed64005fa471cbedbab9c2ae336f0dab', 'Error in call to API function "files/list_folder": The given OAuth 2 access token is malformed.')

2020-04-21 23:46:09 Main         INFO     Starting
2020-04-21 23:46:09 dropbox      INFO     Request to files/list_folder
2020-04-21 23:46:11 root         ERROR    BadInputError('f4ee2cfdb26c419a16c62210d0520794', 'Error in call to API function "files/list_folder": request body: path: Specify the root folder as an empty string rather than as "/".')
Traceback (most recent call last):
  File "/home/drkostas/Insync/OneDrive/Projects/template_python_project/main.py", line 76, in <module>
    main()
  File "/home/drkostas/Insync/OneDrive/Projects/template_python_project/main.py", line 22, in main
    print(cloud_store.ls(path='/'))
  File "/home/drkostas/Insync/OneDrive/Projects/template_python_project/cloudstore/dropbox_cloudstore.py", line 94, in ls
    files_list = cls.__handler__.files_list_folder(path=path)
  File "/home/drkostas/Insync/OneDrive/Projects/template_python_project/venv/lib/python3.6/site-packages/dropbox/base.py", line 2121, in files_list_folder
    None,
  File "/home/drkostas/Insync/OneDrive/Projects/template_python_project/venv/lib/python3.6/site-packages/dropbox/dropbox.py", line 316, in request
    timeout=timeout)
  File "/home/drkostas/Insync/OneDrive/Projects/template_python_project/venv/lib/python3.6/site-packages/dropbox/dropbox.py", line 463, in request_json_string_with_retry
    timeout=timeout)
  File "/home/drkostas/Insync/OneDrive/Projects/template_python_project/venv/lib/python3.6/site-packages/dropbox/dropbox.py", line 566, in request_json_string
    raise BadInputError(request_id, r.text)
dropbox.exceptions.BadInputError: BadInputError('f4ee2cfdb26c419a16c62210d0520794', 'Error in call to API function "files/list_folder": request body: path: Specify the root folder as an empty string rather than as "/".')

2020-04-21 23:46:38 Main         INFO     Starting
2020-04-21 23:46:38 dropbox      INFO     Request to files/list_folder
2020-04-21 23:46:39 root         ERROR    AuthError('d802516cef02b45a7f759996293dd52d', AuthError('invalid_access_token', None))
Traceback (most recent call last):
  File "/home/drkostas/Insync/OneDrive/Projects/template_python_project/main.py", line 76, in <module>
    main()
  File "/home/drkostas/Insync/OneDrive/Projects/template_python_project/main.py", line 22, in main
    print(cloud_store.ls(path='/'))
  File "/home/drkostas/Insync/OneDrive/Projects/template_python_project/cloudstore/dropbox_cloudstore.py", line 94, in ls
    files_list = cls.__handler__.files_list_folder(path=path)
  File "/home/drkostas/Insync/OneDrive/Projects/template_python_project/venv/lib/python3.6/site-packages/dropbox/base.py", line 2121, in files_list_folder
    None,
  File "/home/drkostas/Insync/OneDrive/Projects/template_python_project/venv/lib/python3.6/site-packages/dropbox/dropbox.py", line 316, in request
    timeout=timeout)
  File "/home/drkostas/Insync/OneDrive/Projects/template_python_project/venv/lib/python3.6/site-packages/dropbox/dropbox.py", line 463, in request_json_string_with_retry
    timeout=timeout)
  File "/home/drkostas/Insync/OneDrive/Projects/template_python_project/venv/lib/python3.6/site-packages/dropbox/dropbox.py", line 573, in request_json_string
    raise AuthError(request_id, err)
dropbox.exceptions.AuthError: AuthError('d802516cef02b45a7f759996293dd52d', AuthError('invalid_access_token', None))

2020-04-21 23:47:48 Main         INFO     Starting
2020-04-21 23:47:48 dropbox      INFO     Request to files/list_folder
2020-04-21 23:47:48 root         ERROR    BadInputError('69bc7d68f40e872464003ae6dffd1d76', 'Error in call to API function "files/list_folder": The given OAuth 2 access token is malformed.')
Traceback (most recent call last):
  File "/home/drkostas/Insync/OneDrive/Projects/template_python_project/main.py", line 76, in <module>
    main()
  File "/home/drkostas/Insync/OneDrive/Projects/template_python_project/main.py", line 22, in main
    print(cloud_store.ls(path='/'))
  File "/home/drkostas/Insync/OneDrive/Projects/template_python_project/cloudstore/dropbox_cloudstore.py", line 94, in ls
    files_list = cls.__handler__.files_list_folder(path=path)
  File "/home/drkostas/Insync/OneDrive/Projects/template_python_project/venv/lib/python3.6/site-packages/dropbox/base.py", line 2121, in files_list_folder
    None,
  File "/home/drkostas/Insync/OneDrive/Projects/template_python_project/venv/lib/python3.6/site-packages/dropbox/dropbox.py", line 316, in request
    timeout=timeout)
  File "/home/drkostas/Insync/OneDrive/Projects/template_python_project/venv/lib/python3.6/site-packages/dropbox/dropbox.py", line 463, in request_json_string_with_retry
    timeout=timeout)
  File "/home/drkostas/Insync/OneDrive/Projects/template_python_project/venv/lib/python3.6/site-packages/dropbox/dropbox.py", line 566, in request_json_string
    raise BadInputError(request_id, r.text)
dropbox.exceptions.BadInputError: BadInputError('69bc7d68f40e872464003ae6dffd1d76', 'Error in call to API function "files/list_folder": The given OAuth 2 access token is malformed.')

2020-04-21 23:49:56 Main         INFO     Starting
2020-04-21 23:49:56 dropbox      INFO     Request to files/list_folder
2020-04-21 23:49:57 root         ERROR    BadInputError('44475e9e7afec2a0ded333048c76bbef', 'Error in call to API function "files/list_folder": request body: path: Specify the root folder as an empty string rather than as "/".')
Traceback (most recent call last):
  File "/home/drkostas/Insync/OneDrive/Projects/template_python_project/main.py", line 76, in <module>
    main()
  File "/home/drkostas/Insync/OneDrive/Projects/template_python_project/main.py", line 22, in main
    print(cloud_store.ls(path='/'))
  File "/home/drkostas/Insync/OneDrive/Projects/template_python_project/cloudstore/dropbox_cloudstore.py", line 94, in ls
    files_list = cls.__handler__.files_list_folder(path=path)
  File "/home/drkostas/Insync/OneDrive/Projects/template_python_project/venv/lib/python3.6/site-packages/dropbox/base.py", line 2121, in files_list_folder
    None,
  File "/home/drkostas/Insync/OneDrive/Projects/template_python_project/venv/lib/python3.6/site-packages/dropbox/dropbox.py", line 316, in request
    timeout=timeout)
  File "/home/drkostas/Insync/OneDrive/Projects/template_python_project/venv/lib/python3.6/site-packages/dropbox/dropbox.py", line 463, in request_json_string_with_retry
    timeout=timeout)
  File "/home/drkostas/Insync/OneDrive/Projects/template_python_project/venv/lib/python3.6/site-packages/dropbox/dropbox.py", line 566, in request_json_string
    raise BadInputError(request_id, r.text)
dropbox.exceptions.BadInputError: BadInputError('44475e9e7afec2a0ded333048c76bbef', 'Error in call to API function "files/list_folder": request body: path: Specify the root folder as an empty string rather than as "/".')

2020-04-21 23:50:12 Main         INFO     Starting
2020-04-21 23:50:12 dropbox      INFO     Request to files/list_folder
2020-04-21 23:51:10 Main         INFO     Starting
2020-04-21 23:51:10 dropbox      INFO     Request to files/list_folder
2020-04-22 00:03:32 Main         INFO     Starting
2020-04-22 00:03:32 root         ERROR    __init__() got an unexpected keyword argument 'host'
Traceback (most recent call last):
  File "/home/drkostas/Insync/OneDrive/Projects/template_python_project/main.py", line 81, in <module>
    main()
  File "/home/drkostas/Insync/OneDrive/Projects/template_python_project/main.py", line 23, in main
    data_store = MySqlDataStore(**configuration.get_datastore())
TypeError: __init__() got an unexpected keyword argument 'host'

2020-04-22 00:04:11 Main         INFO     Starting
2020-04-22 00:04:11 root         ERROR    No module named 'MySQLdb'
Traceback (most recent call last):
  File "/home/drkostas/Insync/OneDrive/Projects/template_python_project/main.py", line 81, in <module>
    main()
  File "/home/drkostas/Insync/OneDrive/Projects/template_python_project/main.py", line 23, in main
    data_store = MySqlDataStore(**configuration.get_datastore())
  File "/home/drkostas/Insync/OneDrive/Projects/template_python_project/datastore/mysql_datastore.py", line 28, in __init__
    hostname=hostname, db_name=db_name, port=port)
  File "/home/drkostas/Insync/OneDrive/Projects/template_python_project/datastore/abstract_datastore.py", line 23, in __init__
    port=port)
  File "/home/drkostas/Insync/OneDrive/Projects/template_python_project/datastore/mysql_datastore.py", line 44, in get_connection
    engine = sqlalchemy.create_engine("mysql://{}:{}@{}/{}".format(username, password, hostname, db_name))
  File "/home/drkostas/Insync/OneDrive/Projects/template_python_project/venv/lib/python3.6/site-packages/sqlalchemy/engine/__init__.py", line 479, in create_engine
    return strategy.create(*args, **kwargs)
  File "/home/drkostas/Insync/OneDrive/Projects/template_python_project/venv/lib/python3.6/site-packages/sqlalchemy/engine/strategies.py", line 87, in create
    dbapi = dialect_cls.dbapi(**dbapi_args)
  File "/home/drkostas/Insync/OneDrive/Projects/template_python_project/venv/lib/python3.6/site-packages/sqlalchemy/dialects/mysql/mysqldb.py", line 118, in dbapi
    return __import__("MySQLdb")
ModuleNotFoundError: No module named 'MySQLdb'

2020-04-22 00:08:53 Main         INFO     Starting
2020-04-22 00:08:53 root         ERROR    No module named 'MySQLdb'
Traceback (most recent call last):
  File "/home/drkostas/Insync/OneDrive/Projects/template_python_project/main.py", line 81, in <module>
    main()
  File "/home/drkostas/Insync/OneDrive/Projects/template_python_project/main.py", line 23, in main
    data_store = MySqlDataStore(**configuration.get_datastore())
  File "/home/drkostas/Insync/OneDrive/Projects/template_python_project/datastore/mysql_datastore.py", line 29, in __init__
    hostname=hostname, db_name=db_name, port=port)
  File "/home/drkostas/Insync/OneDrive/Projects/template_python_project/datastore/abstract_datastore.py", line 23, in __init__
    port=port)
  File "/home/drkostas/Insync/OneDrive/Projects/template_python_project/datastore/mysql_datastore.py", line 45, in get_connection
    engine = sqlalchemy.create_engine("mysql://{}:{}@{}/{}".format(username, password, hostname, db_name))
  File "/home/drkostas/Insync/OneDrive/Projects/template_python_project/venv/lib/python3.6/site-packages/sqlalchemy/engine/__init__.py", line 479, in create_engine
    return strategy.create(*args, **kwargs)
  File "/home/drkostas/Insync/OneDrive/Projects/template_python_project/venv/lib/python3.6/site-packages/sqlalchemy/engine/strategies.py", line 87, in create
    dbapi = dialect_cls.dbapi(**dbapi_args)
  File "/home/drkostas/Insync/OneDrive/Projects/template_python_project/venv/lib/python3.6/site-packages/sqlalchemy/dialects/mysql/mysqldb.py", line 118, in dbapi
    return __import__("MySQLdb")
ModuleNotFoundError: No module named 'MySQLdb'

2020-04-22 00:11:11 Main         INFO     Starting
2020-04-22 00:11:11 root         ERROR    No module named 'MySQLdb'
Traceback (most recent call last):
  File "/home/drkostas/Insync/OneDrive/Projects/template_python_project/main.py", line 81, in <module>
    main()
  File "/home/drkostas/Insync/OneDrive/Projects/template_python_project/main.py", line 23, in main
    data_store = MySqlDataStore(**configuration.get_datastore())
  File "/home/drkostas/Insync/OneDrive/Projects/template_python_project/datastore/mysql_datastore.py", line 28, in __init__
    hostname=hostname, db_name=db_name, port=port)
  File "/home/drkostas/Insync/OneDrive/Projects/template_python_project/datastore/abstract_datastore.py", line 23, in __init__
    port=port)
  File "/home/drkostas/Insync/OneDrive/Projects/template_python_project/datastore/mysql_datastore.py", line 44, in get_connection
    engine = sqlalchemy.create_engine("mysql://{}:{}@{}/{}".format(username, password, hostname, db_name))
  File "/home/drkostas/Insync/OneDrive/Projects/template_python_project/venv/lib/python3.6/site-packages/sqlalchemy/engine/__init__.py", line 479, in create_engine
    return strategy.create(*args, **kwargs)
  File "/home/drkostas/Insync/OneDrive/Projects/template_python_project/venv/lib/python3.6/site-packages/sqlalchemy/engine/strategies.py", line 87, in create
    dbapi = dialect_cls.dbapi(**dbapi_args)
  File "/home/drkostas/Insync/OneDrive/Projects/template_python_project/venv/lib/python3.6/site-packages/sqlalchemy/dialects/mysql/mysqldb.py", line 118, in dbapi
    return __import__("MySQLdb")
ModuleNotFoundError: No module named 'MySQLdb'

2020-04-22 00:12:52 Main         INFO     Starting
2020-04-22 00:12:52 root         ERROR    No module named 'MySQLdb'
Traceback (most recent call last):
  File "/home/drkostas/Insync/OneDrive/Projects/template_python_project/main.py", line 81, in <module>
    main()
  File "/home/drkostas/Insync/OneDrive/Projects/template_python_project/main.py", line 23, in main
    data_store = MySqlDataStore(**configuration.get_datastore())
  File "/home/drkostas/Insync/OneDrive/Projects/template_python_project/datastore/mysql_datastore.py", line 28, in __init__
    hostname=hostname, db_name=db_name, port=port)
  File "/home/drkostas/Insync/OneDrive/Projects/template_python_project/datastore/abstract_datastore.py", line 23, in __init__
    port=port)
  File "/home/drkostas/Insync/OneDrive/Projects/template_python_project/datastore/mysql_datastore.py", line 44, in get_connection
    engine = sqlalchemy.create_engine("mysql://{}:{}@{}/{}".format(username, password, hostname, db_name))
  File "/home/drkostas/Insync/OneDrive/Projects/template_python_project/venv/lib/python3.6/site-packages/sqlalchemy/engine/__init__.py", line 479, in create_engine
    return strategy.create(*args, **kwargs)
  File "/home/drkostas/Insync/OneDrive/Projects/template_python_project/venv/lib/python3.6/site-packages/sqlalchemy/engine/strategies.py", line 87, in create
    dbapi = dialect_cls.dbapi(**dbapi_args)
  File "/home/drkostas/Insync/OneDrive/Projects/template_python_project/venv/lib/python3.6/site-packages/sqlalchemy/dialects/mysql/mysqldb.py", line 118, in dbapi
    return __import__("MySQLdb")
ModuleNotFoundError: No module named 'MySQLdb'

2020-04-22 00:29:20 Main         INFO     Starting
2020-04-22 00:29:20 root         ERROR    No module named 'MySQLdb'
Traceback (most recent call last):
  File "/home/drkostas/Insync/OneDrive/Projects/template_python_project/main.py", line 81, in <module>
    main()
  File "/home/drkostas/Insync/OneDrive/Projects/template_python_project/main.py", line 23, in main
    data_store = MySqlDataStore(**configuration.get_datastore())
  File "/home/drkostas/Insync/OneDrive/Projects/template_python_project/datastore/mysql_datastore.py", line 28, in __init__
    hostname=hostname, db_name=db_name, port=port)
  File "/home/drkostas/Insync/OneDrive/Projects/template_python_project/datastore/abstract_datastore.py", line 23, in __init__
    port=port)
  File "/home/drkostas/Insync/OneDrive/Projects/template_python_project/datastore/mysql_datastore.py", line 44, in get_connection
    engine = sqlalchemy.create_engine("mysql://{}:{}@{}/{}".format(username, password, hostname, db_name))
  File "/home/drkostas/Insync/OneDrive/Projects/template_python_project/venv/lib/python3.6/site-packages/sqlalchemy/engine/__init__.py", line 479, in create_engine
    return strategy.create(*args, **kwargs)
  File "/home/drkostas/Insync/OneDrive/Projects/template_python_project/venv/lib/python3.6/site-packages/sqlalchemy/engine/strategies.py", line 87, in create
    dbapi = dialect_cls.dbapi(**dbapi_args)
  File "/home/drkostas/Insync/OneDrive/Projects/template_python_project/venv/lib/python3.6/site-packages/sqlalchemy/dialects/mysql/mysqldb.py", line 118, in dbapi
    return __import__("MySQLdb")
ModuleNotFoundError: No module named 'MySQLdb'

2020-04-22 00:37:39 Main         INFO     Starting
2020-04-22 00:37:39 root         ERROR    Can't instantiate abstract class MySqlDataStore with abstract methods __exit__, create_table, delete_from_table, drop_table, insert_into_table, select_from_table, show_tables, truncate_table, update_table
Traceback (most recent call last):
  File "/home/drkostas/Insync/OneDrive/Projects/template_python_project/main.py", line 81, in <module>
    main()
  File "/home/drkostas/Insync/OneDrive/Projects/template_python_project/main.py", line 23, in main
    data_store = MySqlDataStore(**configuration.get_datastore())
TypeError: Can't instantiate abstract class MySqlDataStore with abstract methods __exit__, create_table, delete_from_table, drop_table, insert_into_table, select_from_table, show_tables, truncate_table, update_table

2020-04-22 00:39:24 Main         INFO     Starting
2020-04-22 00:39:24 root         ERROR    Can't instantiate abstract class MySqlDataStore with abstract methods __exit__, create_table, delete_from_table, drop_table, insert_into_table, select_from_table, show_tables, truncate_table, update_table
Traceback (most recent call last):
  File "/home/drkostas/Insync/OneDrive/Projects/template_python_project/main.py", line 81, in <module>
    main()
  File "/home/drkostas/Insync/OneDrive/Projects/template_python_project/main.py", line 23, in main
    data_store = MySqlDataStore(**configuration.get_datastore())
TypeError: Can't instantiate abstract class MySqlDataStore with abstract methods __exit__, create_table, delete_from_table, drop_table, insert_into_table, select_from_table, show_tables, truncate_table, update_table

2020-04-22 00:41:01 Main         INFO     Starting
2020-04-22 00:41:01 root         ERROR    Can't instantiate abstract class MySqlDataStore with abstract methods __exit__, create_table, delete_from_table, drop_table, insert_into_table, select_from_table, show_tables, truncate_table, update_table
Traceback (most recent call last):
  File "/home/drkostas/Insync/OneDrive/Projects/template_python_project/main.py", line 81, in <module>
    main()
  File "/home/drkostas/Insync/OneDrive/Projects/template_python_project/main.py", line 23, in main
    data_store = MySqlDataStore(**configuration.get_datastore())
TypeError: Can't instantiate abstract class MySqlDataStore with abstract methods __exit__, create_table, delete_from_table, drop_table, insert_into_table, select_from_table, show_tables, truncate_table, update_table

2020-04-22 00:41:43 Main         INFO     Starting
2020-04-22 00:41:43 root         ERROR    Can't instantiate abstract class MySqlDataStore with abstract methods create_table, delete_from_table, drop_table, insert_into_table, select_from_table, show_tables, truncate_table, update_table
Traceback (most recent call last):
  File "/home/drkostas/Insync/OneDrive/Projects/template_python_project/main.py", line 81, in <module>
    main()
  File "/home/drkostas/Insync/OneDrive/Projects/template_python_project/main.py", line 23, in main
    data_store = MySqlDataStore(**configuration.get_datastore())
TypeError: Can't instantiate abstract class MySqlDataStore with abstract methods create_table, delete_from_table, drop_table, insert_into_table, select_from_table, show_tables, truncate_table, update_table

2020-04-22 00:43:18 Main         INFO     Starting
2020-04-22 00:43:18 root         ERROR    Can't instantiate abstract class MySqlDataStore with abstract methods create_table, delete_from_table, drop_table, insert_into_table, select_from_table, show_tables, truncate_table, update_table
Traceback (most recent call last):
  File "/home/drkostas/Insync/OneDrive/Projects/template_python_project/main.py", line 81, in <module>
    main()
  File "/home/drkostas/Insync/OneDrive/Projects/template_python_project/main.py", line 23, in main
    data_store = MySqlDataStore(**configuration.get_datastore())
TypeError: Can't instantiate abstract class MySqlDataStore with abstract methods create_table, delete_from_table, drop_table, insert_into_table, select_from_table, show_tables, truncate_table, update_table

2020-04-22 01:13:16 Main         INFO     Starting
2020-04-22 01:13:18 dropbox      INFO     Request to files/list_folder
2020-04-22 01:20:46 Main         INFO     Starting
2020-04-22 01:20:48 root         ERROR    'CMySQLCursor' object has no attribute 'flush'
Traceback (most recent call last):
  File "/home/drkostas/Insync/OneDrive/Projects/template_python_project/main.py", line 82, in <module>
    main()
  File "/home/drkostas/Insync/OneDrive/Projects/template_python_project/main.py", line 26, in main
    data_store.__exit__()
  File "/home/drkostas/Insync/OneDrive/Projects/template_python_project/datastore/mysql_datastore.py", line 195, in __exit__
    cls.__cursor__.flush()
AttributeError: 'CMySQLCursor' object has no attribute 'flush'

2020-04-22 01:21:45 Main         INFO     Starting
2020-04-22 01:21:46 root         ERROR    'CMySQLCursor' object has no attribute 'commit'
Traceback (most recent call last):
  File "/home/drkostas/Insync/OneDrive/Projects/template_python_project/main.py", line 82, in <module>
    main()
  File "/home/drkostas/Insync/OneDrive/Projects/template_python_project/main.py", line 26, in main
    data_store.__exit__()
  File "/home/drkostas/Insync/OneDrive/Projects/template_python_project/datastore/mysql_datastore.py", line 195, in __exit__
    cls.__cursor__.commit()
AttributeError: 'CMySQLCursor' object has no attribute 'commit'

2020-04-22 01:42:17 Main         INFO     Starting
2020-04-22 01:42:20 dropbox      INFO     Request to files/list_folder
2020-04-22 21:12:45 Main         INFO     Starting
2020-04-22 21:12:47 dropbox      INFO     Request to files/list_folder
2020-04-22 21:19:16 Main         INFO     Starting
2020-04-22 21:19:17 dropbox      INFO     Request to files/list_folder
2020-04-22 21:20:31 Main         INFO     Starting
2020-04-22 21:20:33 dropbox      INFO     Request to files/list_folder
2020-04-22 21:21:44 Main         INFO     Starting
2020-04-22 21:21:46 dropbox      INFO     Request to files/list_folder
2020-04-22 21:21:56 Main         INFO     Starting
2020-04-22 21:21:58 dropbox      INFO     Request to files/list_folder
2020-04-22 21:26:39 Main         INFO     Starting
2020-04-22 21:26:41 dropbox      INFO     Request to files/list_folder
2020-04-22 21:29:21 Main         INFO     Starting
2020-04-22 21:29:23 Main         INFO     Tables in current DB: [('test_table',)]
2020-04-22 21:29:23 dropbox      INFO     Request to files/list_folder
2020-04-22 21:29:24 Main         INFO     List of files in Dropbox root: ['template.html', 'stream.png']
2020-04-22 21:52:58 Main         INFO     Starting
2020-04-22 21:53:00 Main         INFO     Tables in current DB: [('test_table',)]
2020-04-22 21:53:00 dropbox      INFO     Request to files/list_folder
2020-04-22 21:53:01 Main         INFO     List of files in Dropbox root: ['template.html', 'stream.png']
2020-04-22 22:04:54 Main         INFO     Starting
2020-04-22 22:04:54 root         ERROR    [Errno 2] No such file or directory: '/home/drkostas/Insync/OneDrive/Projects/template_python_project/src/configuration/../tests/test_data/test_configuration/yml_schema.json'
Traceback (most recent call last):
  File "/home/drkostas/Insync/OneDrive/Projects/template_python_project/src/main.py", line 89, in <module>
    main()
  File "/home/drkostas/Insync/OneDrive/Projects/template_python_project/src/main.py", line 75, in main
    configuration = Configuration(config_src=args.config_file)
  File "/home/drkostas/Insync/OneDrive/Projects/template_python_project/src/configuration/configuration.py", line 32, in __init__
    configuration_schema = cls.load_configuration_schema(config_schema_path=config_schema_path)
  File "/home/drkostas/Insync/OneDrive/Projects/template_python_project/src/configuration/configuration.py", line 45, in load_configuration_schema
    with open('/'.join([os.path.dirname(os.path.realpath(__file__)), config_schema_path])) as f:
FileNotFoundError: [Errno 2] No such file or directory: '/home/drkostas/Insync/OneDrive/Projects/template_python_project/src/configuration/../tests/test_data/test_configuration/yml_schema.json'

2020-04-22 22:05:06 Main         INFO     Starting
2020-04-22 22:05:06 root         ERROR    'property' is a required property

Failed validating 'required' in schema:
    {'$schema': 'http://json-schema.org/draft-04/schema#',
     'additionalProperties': False,
     'definitions': {'property2': {'additionalProperties': False,
                                   'properties': {'subproperty1': {'enum': [1,
                                                                            2],
                                                                   'type': 'number'},
                                                  'subproperty2': {'type': 'array'}},
                                   'required': ['subproperty1',
                                                'subproperty2'],
                                   'type': 'object'}},
     'properties': {'property1': {'type': 'string'},
                    'property2': {'$ref': '#/definitions/property2'}},
     'required': ['property', 'property2'],
     'type': 'object'}

On instance:
    {'propert2': [{'subproperty1': 1}, {'subproperty2': ['123', '234']}],
     'property1': 'test'}
Traceback (most recent call last):
  File "/home/drkostas/Insync/OneDrive/Projects/template_python_project/src/main.py", line 89, in <module>
    main()
  File "/home/drkostas/Insync/OneDrive/Projects/template_python_project/src/main.py", line 75, in main
    configuration = Configuration(config_src=args.config_file)
  File "/home/drkostas/Insync/OneDrive/Projects/template_python_project/src/configuration/configuration.py", line 37, in __init__
    validate_json_schema(cls.config, configuration_schema)
  File "/home/drkostas/Insync/OneDrive/Projects/template_python_project/venv/lib/python3.6/site-packages/jsonschema/validators.py", line 934, in validate
    raise error
jsonschema.exceptions.ValidationError: 'property' is a required property

Failed validating 'required' in schema:
    {'$schema': 'http://json-schema.org/draft-04/schema#',
     'additionalProperties': False,
     'definitions': {'property2': {'additionalProperties': False,
                                   'properties': {'subproperty1': {'enum': [1,
                                                                            2],
                                                                   'type': 'number'},
                                                  'subproperty2': {'type': 'array'}},
                                   'required': ['subproperty1',
                                                'subproperty2'],
                                   'type': 'object'}},
     'properties': {'property1': {'type': 'string'},
                    'property2': {'$ref': '#/definitions/property2'}},
     'required': ['property', 'property2'],
     'type': 'object'}

On instance:
    {'propert2': [{'subproperty1': 1}, {'subproperty2': ['123', '234']}],
     'property1': 'test'}

2020-04-22 22:05:27 Main         INFO     Starting
2020-04-22 22:05:27 root         ERROR    'property2' is a required property

Failed validating 'required' in schema:
    {'$schema': 'http://json-schema.org/draft-04/schema#',
     'additionalProperties': False,
     'definitions': {'property2': {'additionalProperties': False,
                                   'properties': {'subproperty1': {'enum': [1,
                                                                            2],
                                                                   'type': 'number'},
                                                  'subproperty2': {'type': 'array'}},
                                   'required': ['subproperty1',
                                                'subproperty2'],
                                   'type': 'object'}},
     'properties': {'property1': {'type': 'string'},
                    'property2': {'$ref': '#/definitions/property2'}},
     'required': ['property1', 'property2'],
     'type': 'object'}

On instance:
    {'propert2': [{'subproperty1': 1}, {'subproperty2': ['123', '234']}],
     'property1': 'test'}
Traceback (most recent call last):
  File "/home/drkostas/Insync/OneDrive/Projects/template_python_project/src/main.py", line 89, in <module>
    main()
  File "/home/drkostas/Insync/OneDrive/Projects/template_python_project/src/main.py", line 75, in main
    configuration = Configuration(config_src=args.config_file)
  File "/home/drkostas/Insync/OneDrive/Projects/template_python_project/src/configuration/configuration.py", line 37, in __init__
    validate_json_schema(cls.config, configuration_schema)
  File "/home/drkostas/Insync/OneDrive/Projects/template_python_project/venv/lib/python3.6/site-packages/jsonschema/validators.py", line 934, in validate
    raise error
jsonschema.exceptions.ValidationError: 'property2' is a required property

Failed validating 'required' in schema:
    {'$schema': 'http://json-schema.org/draft-04/schema#',
     'additionalProperties': False,
     'definitions': {'property2': {'additionalProperties': False,
                                   'properties': {'subproperty1': {'enum': [1,
                                                                            2],
                                                                   'type': 'number'},
                                                  'subproperty2': {'type': 'array'}},
                                   'required': ['subproperty1',
                                                'subproperty2'],
                                   'type': 'object'}},
     'properties': {'property1': {'type': 'string'},
                    'property2': {'$ref': '#/definitions/property2'}},
     'required': ['property1', 'property2'],
     'type': 'object'}

On instance:
    {'propert2': [{'subproperty1': 1}, {'subproperty2': ['123', '234']}],
     'property1': 'test'}

2020-04-22 22:05:50 Main         INFO     Starting
2020-04-22 22:05:50 root         ERROR    [{'subproperty1': 1}, {'subproperty2': ['123', '234']}] is not of type 'object'

Failed validating 'type' in schema['properties']['property2']:
    {'additionalProperties': False,
     'properties': {'subproperty1': {'enum': [1, 2], 'type': 'number'},
                    'subproperty2': {'type': 'array'}},
     'required': ['subproperty1', 'subproperty2'],
     'type': 'object'}

On instance['property2']:
    [{'subproperty1': 1}, {'subproperty2': ['123', '234']}]
Traceback (most recent call last):
  File "/home/drkostas/Insync/OneDrive/Projects/template_python_project/src/main.py", line 89, in <module>
    main()
  File "/home/drkostas/Insync/OneDrive/Projects/template_python_project/src/main.py", line 75, in main
    configuration = Configuration(config_src=args.config_file)
  File "/home/drkostas/Insync/OneDrive/Projects/template_python_project/src/configuration/configuration.py", line 37, in __init__
    validate_json_schema(cls.config, configuration_schema)
  File "/home/drkostas/Insync/OneDrive/Projects/template_python_project/venv/lib/python3.6/site-packages/jsonschema/validators.py", line 934, in validate
    raise error
jsonschema.exceptions.ValidationError: [{'subproperty1': 1}, {'subproperty2': ['123', '234']}] is not of type 'object'

Failed validating 'type' in schema['properties']['property2']:
    {'additionalProperties': False,
     'properties': {'subproperty1': {'enum': [1, 2], 'type': 'number'},
                    'subproperty2': {'type': 'array'}},
     'required': ['subproperty1', 'subproperty2'],
     'type': 'object'}

On instance['property2']:
    [{'subproperty1': 1}, {'subproperty2': ['123', '234']}]

2020-04-22 22:09:03 Main         INFO     Starting
2020-04-22 22:09:03 root         ERROR    [{'subproperty1': 1}, {'subproperty2': ['123', '234']}] is not of type 'object'

Failed validating 'type' in schema['properties']['property2']:
    {'additionalProperties': False,
     'properties': {'subproperty1': {'enum': [1, 2], 'type': 'number'},
                    'subproperty2': {'type': 'array'}},
     'required': ['subproperty1', 'subproperty2'],
     'type': 'object'}

On instance['property2']:
    [{'subproperty1': 1}, {'subproperty2': ['123', '234']}]
Traceback (most recent call last):
  File "/home/drkostas/Insync/OneDrive/Projects/template_python_project/src/main.py", line 89, in <module>
    main()
  File "/home/drkostas/Insync/OneDrive/Projects/template_python_project/src/main.py", line 75, in main
    configuration = Configuration(config_src=args.config_file)
  File "/home/drkostas/Insync/OneDrive/Projects/template_python_project/src/configuration/configuration.py", line 37, in __init__
    validate_json_schema(cls.config, configuration_schema)
  File "/home/drkostas/Insync/OneDrive/Projects/template_python_project/venv/lib/python3.6/site-packages/jsonschema/validators.py", line 934, in validate
    raise error
jsonschema.exceptions.ValidationError: [{'subproperty1': 1}, {'subproperty2': ['123', '234']}] is not of type 'object'

Failed validating 'type' in schema['properties']['property2']:
    {'additionalProperties': False,
     'properties': {'subproperty1': {'enum': [1, 2], 'type': 'number'},
                    'subproperty2': {'type': 'array'}},
     'required': ['subproperty1', 'subproperty2'],
     'type': 'object'}

On instance['property2']:
    [{'subproperty1': 1}, {'subproperty2': ['123', '234']}]

2020-04-22 22:10:25 Main         INFO     Starting
2020-04-22 22:10:25 root         ERROR    'datastore'
Traceback (most recent call last):
  File "/home/drkostas/Insync/OneDrive/Projects/template_python_project/src/main.py", line 89, in <module>
    main()
  File "/home/drkostas/Insync/OneDrive/Projects/template_python_project/src/main.py", line 75, in main
    configuration = Configuration(config_src=args.config_file)
  File "/home/drkostas/Insync/OneDrive/Projects/template_python_project/src/configuration/configuration.py", line 39, in __init__
    cls.datastore = cls.config['datastore']
KeyError: 'datastore'

2020-04-22 23:02:37 Main         INFO     Starting
2020-04-22 23:02:39 Main         INFO     Tables in current DB: [('test_table',)]
2020-04-22 23:02:39 dropbox      INFO     Request to files/list_folder
2020-04-22 23:02:40 Main         INFO     List of files in Dropbox root: ['template.html', 'stream.png']
2020-04-22 23:29:06 Main         INFO     Starting
2020-04-22 23:29:08 Main         INFO     Tables in current DB: [('test_table',)]
2020-04-22 23:29:08 dropbox      INFO     Request to files/list_folder
2020-04-22 23:29:09 Main         INFO     List of files in Dropbox root: ['template.html', 'stream.png']
2020-04-23 02:48:55 Main         INFO     Starting
2020-04-23 02:48:57 Main         INFO     Tables in current DB: [('test_table',)]
2020-04-23 02:48:57 dropbox      INFO     Request to files/list_folder
2020-04-23 02:48:58 Main         INFO     List of files in Dropbox root: ['testss', 'template.html', 'stream.png']
2020-04-23 21:33:37 Main         INFO     Starting
2020-04-23 21:33:39 Main         INFO     Starting
2020-04-23 21:33:39 Main         INFO     Tables in current DB: [('test_table',)]
2020-04-23 21:33:39 dropbox      INFO     Request to files/list_folder
2020-04-23 21:33:41 Main         INFO     Starting
2020-04-23 21:33:41 Main         INFO     Tables in current DB: [('test_table',)]
2020-04-23 21:33:41 dropbox      INFO     Request to files/list_folder
2020-04-23 21:33:42 Main         INFO     List of files in Dropbox root: ['template.html', 'stream.png']
2020-04-23 21:33:43 Main         INFO     Tables in current DB: [('test_table',)]
2020-04-23 21:33:43 dropbox      INFO     Request to files/list_folder
2020-04-23 21:33:43 Main         INFO     List of files in Dropbox root: ['template.html', 'stream.png']
2020-04-23 21:57:13 Main         INFO     Starting
2020-04-23 21:57:15 Main         INFO     Tables in current DB: [('test_table',)]
2020-04-23 21:57:16 Main         INFO     Tables in current DB: [('orders',), ('test_table',)]
2020-04-23 21:57:16 Main         INFO     Tables in current DB: [('test_table',)]
2020-04-23 21:57:16 dropbox      INFO     Request to files/list_folder
2020-04-23 21:57:17 Main         INFO     List of files in Dropbox root: []
2020-04-23 21:57:17 Main         INFO     Uploading file /python_template/file1.txt with content: test file cotent
2020-04-23 21:57:17 dropbox      INFO     Request to files/upload
2020-04-23 21:57:17 root         ERROR    expected request_binary as binary type, got <class '_io.StringIO'>
Traceback (most recent call last):
  File "/home/drkostas/Insync/OneDrive/Projects/template_python_project/src/main.py", line 107, in <module>
    main()
  File "/home/drkostas/Insync/OneDrive/Projects/template_python_project/src/main.py", line 94, in main
    cloud_store.upload_file(file_stream=StringIO(file_content), upload_path=upload_path)
  File "/home/drkostas/Insync/OneDrive/Projects/template_python_project/src/cloudstore/dropbox_cloudstore.py", line 47, in upload_file
    self.__handler__.files_upload(f=file_stream, path=upload_path, mode=files.WriteMode(write_mode))
  File "/home/drkostas/Insync/OneDrive/Projects/template_python_project/venv/lib/python3.6/site-packages/dropbox/base.py", line 2963, in files_upload
    f,
  File "/home/drkostas/Insync/OneDrive/Projects/template_python_project/venv/lib/python3.6/site-packages/dropbox/dropbox.py", line 316, in request
    timeout=timeout)
  File "/home/drkostas/Insync/OneDrive/Projects/template_python_project/venv/lib/python3.6/site-packages/dropbox/dropbox.py", line 466, in request_json_string_with_retry
    timeout=timeout)
  File "/home/drkostas/Insync/OneDrive/Projects/template_python_project/venv/lib/python3.6/site-packages/dropbox/dropbox.py", line 522, in request_json_string
    type(request_binary))
TypeError: expected request_binary as binary type, got <class '_io.StringIO'>

2020-04-23 21:58:40 Main         INFO     Starting
2020-04-23 21:58:42 Main         INFO     Tables in current DB: [('test_table',)]
2020-04-23 21:58:42 Main         INFO     Tables in current DB: [('orders',), ('test_table',)]
2020-04-23 21:58:43 Main         INFO     Tables in current DB: [('test_table',)]
2020-04-23 21:58:43 dropbox      INFO     Request to files/list_folder
2020-04-23 21:58:43 Main         INFO     List of files in Dropbox root: []
2020-04-23 21:58:43 Main         INFO     Uploading file /python_template/file1.txt with content: test file cotent
2020-04-23 21:58:43 root         ERROR    a bytes-like object is required, not 'str'
Traceback (most recent call last):
  File "/home/drkostas/Insync/OneDrive/Projects/template_python_project/src/main.py", line 107, in <module>
    main()
  File "/home/drkostas/Insync/OneDrive/Projects/template_python_project/src/main.py", line 94, in main
    cloud_store.upload_file(file_stream=BytesIO(file_content), upload_path=upload_path)
TypeError: a bytes-like object is required, not 'str'

2020-04-23 22:00:23 Main         INFO     Starting
2020-04-23 22:00:25 Main         INFO     Tables in current DB: [('test_table',)]
2020-04-23 22:00:25 Main         INFO     Tables in current DB: [('orders',), ('test_table',)]
2020-04-23 22:00:26 Main         INFO     Tables in current DB: [('test_table',)]
2020-04-23 22:00:26 dropbox      INFO     Request to files/list_folder
2020-04-23 22:00:26 Main         INFO     List of files in Dropbox root: []
2020-04-23 22:00:26 Main         INFO     Uploading file /python_template/file1.txt with content: test file cotent
2020-04-23 22:00:26 dropbox      INFO     Request to files/upload
2020-04-23 22:00:28 dropbox      INFO     Request to files/list_folder
2020-04-23 22:00:29 Main         INFO     List of files in Dropbox root: ['file1.txt']
2020-04-23 22:00:29 dropbox      INFO     Request to files/download
2020-04-23 22:00:29 Main         INFO     Downloaded file and its content is: test file cotent
2020-04-23 22:00:29 dropbox      INFO     Request to files/delete_v2
2020-04-23 22:00:30 Main         INFO     Deleting file /python_template/file1.txt..
2020-04-23 22:00:30 dropbox      INFO     Request to files/list_folder
2020-04-23 22:00:31 Main         INFO     List of files in Dropbox root: []
2020-04-23 22:01:01 Main         INFO     Starting
2020-04-23 22:01:03 Main         INFO     Tables in current DB: [('test_table',)]
2020-04-23 22:01:03 Main         INFO     Tables in current DB: [('orders',), ('test_table',)]
2020-04-23 22:01:04 Main         INFO     Tables in current DB: [('test_table',)]
2020-04-23 22:01:04 dropbox      INFO     Request to files/list_folder
2020-04-23 22:01:04 Main         INFO     List of files in Dropbox root: []
2020-04-23 22:01:04 Main         INFO     Uploading file /python_template/file1.txt with content: test file content
2020-04-23 22:01:04 dropbox      INFO     Request to files/upload
2020-04-23 22:01:06 dropbox      INFO     Request to files/list_folder
2020-04-23 22:01:06 Main         INFO     List of files in Dropbox root: ['file1.txt']
2020-04-23 22:01:06 dropbox      INFO     Request to files/download
2020-04-23 22:01:07 Main         INFO     Downloaded file and its content is: b'test file content'
2020-04-23 22:01:07 dropbox      INFO     Request to files/delete_v2
2020-04-23 22:01:08 Main         INFO     Deleting file /python_template/file1.txt..
2020-04-23 22:01:08 dropbox      INFO     Request to files/list_folder
2020-04-23 22:01:08 Main         INFO     List of files in Dropbox root: []
2020-04-23 22:10:06 Main         INFO     Starting
2020-04-23 22:10:08 Main         INFO     Tables in current DB: [('test_table',)]
2020-04-23 22:10:08 Main         INFO     Creating Table: orders
2020-04-23 22:10:09 Main         INFO     Tables in current DB: [('orders',), ('test_table',)]
2020-04-23 22:10:09 Main         INFO     Inserting into orders the values: (1 simple newyork)..
2020-04-23 22:10:09 Main         INFO     SELECT * FROM orders;
[(1, 'plain', 'new_york')]
2020-04-23 22:10:09 Main         INFO     Deleting the inserted row from table orders..
2020-04-23 22:10:10 Main         INFO     SELECT * FROM orders;
[]
2020-04-23 22:10:10 Main         INFO     Dropping Table: orders
2020-04-23 22:10:10 Main         INFO     Tables in current DB: [('test_table',)]
2020-04-23 22:10:10 dropbox      INFO     Request to files/list_folder
2020-04-23 22:10:11 Main         INFO     List of files in Dropbox root: []
2020-04-23 22:10:11 Main         INFO     Uploading file /python_template/file1.txt with content: test file content
2020-04-23 22:10:11 dropbox      INFO     Request to files/upload
2020-04-23 22:10:12 dropbox      INFO     Request to files/list_folder
2020-04-23 22:10:13 Main         INFO     List of files in Dropbox root: ['file1.txt']
2020-04-23 22:10:13 dropbox      INFO     Request to files/download
2020-04-23 22:10:13 Main         INFO     Downloaded file and its content is: b'test file content'
2020-04-23 22:10:13 dropbox      INFO     Request to files/delete_v2
2020-04-23 22:10:14 Main         INFO     Deleting file /python_template/file1.txt..
2020-04-23 22:10:14 dropbox      INFO     Request to files/list_folder
2020-04-23 22:10:15 Main         INFO     List of files in Dropbox root: []
2020-04-23 22:12:49 Main         INFO     Starting
2020-04-23 22:12:51 Main         INFO     

MYSQL EXAMPLE
-------------------------
2020-04-23 22:12:51 Main         INFO     

Tables in current DB: [('test_table',)]
2020-04-23 22:12:51 Main         INFO     Creating Table: orders
2020-04-23 22:12:51 Main         INFO     Tables in current DB:
[('orders',), ('test_table',)]
2020-04-23 22:12:51 Main         INFO     Inserting into orders the values:
(1 simple newyork)..
2020-04-23 22:12:52 Main         INFO     SELECT * FROM orders;
[(1, 'plain', 'new_york')]
2020-04-23 22:12:52 Main         INFO     Deleting the inserted row from table orders..
2020-04-23 22:12:52 Main         INFO     SELECT * FROM orders;
[]
2020-04-23 22:12:52 Main         INFO     Dropping Table: orders
2020-04-23 22:12:53 Main         INFO     Tables in current DB:
[('test_table',)]
2020-04-23 22:12:53 Main         INFO     

DROPBOX EXAMPLE
-------------------------
2020-04-23 22:12:53 dropbox      INFO     Request to files/list_folder
2020-04-23 22:12:53 Main         INFO     List of files in Dropbox /python_template:
[]
2020-04-23 22:12:53 Main         INFO     Uploading file /python_template/file1.txt with content:
test file content
2020-04-23 22:12:53 dropbox      INFO     Request to files/upload
2020-04-23 22:12:55 dropbox      INFO     Request to files/list_folder
2020-04-23 22:12:55 Main         INFO     List of files in Dropbox /python_template:
['file1.txt']
2020-04-23 22:12:55 dropbox      INFO     Request to files/download
2020-04-23 22:12:56 Main         INFO     Downloaded file and its content is:
b'test file content'
2020-04-23 22:12:56 dropbox      INFO     Request to files/delete_v2
2020-04-23 22:12:57 Main         INFO     Deleting file /python_template/file1.txt..
2020-04-23 22:12:57 dropbox      INFO     Request to files/list_folder
2020-04-23 22:12:57 Main         INFO     List of files in Dropbox /python_template:
[]
